<mujoco model="KinovaGen3_7dof_description">
  <compiler angle="radian"/>

  <compiler angle="radian" meshdir="meshes"/>

  <option timestep="0.001" gravity="0 0 -9.81">
      <flag contact="enable" energy="enable" gravity="enable"/>
  </option>

  <asset>
    <mesh name="base_link" file="base_link.STL"/>
    <mesh name="link1" file="link1.STL"/>
    <mesh name="link2" file="link2.STL"/>
    <mesh name="link3" file="link3.STL"/>
    <mesh name="link4" file="link4.STL"/>
    <mesh name="link5" file="link5.STL"/>
    <mesh name="link6" file="link6.STL"/>
    <mesh name="link7" file="link7.STL"/>
    <mesh name="link_tool" file="link_tool.STL"/>

    <texture type="skybox" builtin="gradient" rgb1="0.3 0.5 0.7" rgb2="0 0 0" width="512" height="3072"/>
    <texture type="2d" name="groundplane" builtin="checker" mark="edge" rgb1="0.2 0.3 0.4" rgb2="0.1 0.2 0.3" markrgb="0.8 0.8 0.8" width="300" height="300"/>
    <material name="groundplane" texture="groundplane" texuniform="true" texrepeat="5 5" reflectance="0.2"/>

  </asset>

  <worldbody>
    <light pos="0 0 1.5" dir="0 0 -1" directional="true"/>
    <geom name="floor" size="0 0 0.05" type="plane" material="groundplane"/>

    <geom type="mesh" rgba="0.79216 0.81961 0.93333 1" mesh="base_link"/>
    <body name="link1" pos="0 0 0.14045" quat="0.707105 -0.707108 0 0">
      <inertial pos="6.1995e-05 -0.1434 -0.0026309" quat="-0.192646 0.680358 0.192646 0.680358" mass="0.0098259" diaginertia="2.0113e-05 1.08692e-05 1.08648e-05"/>
      <joint name="joint1" pos="0 0 0" axis="0 -1 0" range="-3.14 3.14" actuatorfrcrange="-50 50"/>
      <geom type="mesh" rgba="0.79216 0.81961 0.93333 1" mesh="link1"/>
      <body name="link2" pos="0 -0.1434 0" quat="0.707105 0.707108 0 0">
        <inertial pos="6.6154e-05 -0.022697 0.10136" quat="0.703792 -0.068862 0.0687948 0.703706" mass="0.1388" diaginertia="0.000518167 0.00047188 0.000182613"/>
        <joint name="joint2" pos="0 0 0" axis="0 -1 0" range="-3.14 3.14" actuatorfrcrange="-50 50"/>
        <geom type="mesh" rgba="0.79216 0.81961 0.93333 1" mesh="link2"/>
        <body name="link3" pos="6.1995e-05 -0.010643 0.1956" quat="0.707105 -0.707108 0 0">
          <inertial pos="-1.9641e-05 -0.13706 0.011816" quat="0.521005 0.477994 -0.478053 0.521096" mass="0.13799" diaginertia="0.00110769 0.0010686 0.000188415"/>
          <joint name="joint3" pos="0 0 0" axis="0 -1 0" range="-3.14 3.14" actuatorfrcrange="-50 50"/>
          <geom type="mesh" rgba="0.79216 0.81961 0.93333 1" mesh="link3"/>
          <body name="link4" pos="0 -0.2242 -0.0202" quat="0.707105 0.707108 0 0">
            <inertial pos="3.0089e-07 0.00016564 0.07622" quat="0.704851 -0.0569735 0.057067 0.704757" mass="0.35459" diaginertia="0.000582949 0.00049578 0.000218841"/>
            <joint name="joint4" pos="0 0 0" axis="0 -1 0" range="-3.14 3.14" actuatorfrcrange="-50 50"/>
            <geom type="mesh" rgba="0.75294 0.75294 0.75294 1" mesh="link4"/>
            <body name="link5" pos="0 0.0084 0.2203" quat="0.707105 -0.707108 0 0">
              <inertial pos="-1.4383e-07 -0.050174 0.0092547" quat="0.558024 0.434353 -0.434307 0.557965" mass="0.25081" diaginertia="0.000221641 0.0001993 0.000128829"/>
              <joint name="joint5" pos="0 0 0" axis="0 -1 0" range="-3.14 3.14" actuatorfrcrange="-11 11"/>
              <geom type="mesh" rgba="0.75294 0.75294 0.75294 1" mesh="link5"/>
              <body name="link6" pos="0 -0.0931 -0.01205" quat="0.707105 0.707108 0 0">
                <inertial pos="-9.2746e-08 0.0034219 0.04541" quat="0.699159 -0.105489 0.105481 0.69923" mass="0.25081" diaginertia="0.000235441 0.00021273 0.000128459"/>
                <joint name="joint6" pos="0 0 0" axis="0 -1 0" range="-3.14 3.14" actuatorfrcrange="-11 11"/>
                <geom type="mesh" rgba="0.75294 0.75294 0.75294 1" mesh="link6"/>
                <body name="link7" pos="0 0.01265 0.1178" quat="0.707105 -0.707108 0 0">
                  <inertial pos="-8.7397e-05 -0.084761 0.0026465" quat="0.502695 0.498346 -0.503243 0.495677" mass="0.53835" diaginertia="0.000365541 0.000311085 0.000275824"/>
                  <joint name="joint7" pos="0 0 0" axis="0 -1 0" range="-3.14 3.14" actuatorfrcrange="-11 11"/>
                  <geom type="mesh" rgba="0.75294 0.75294 0.75294 1" mesh="link7"/>
                  <body name="link_tool" pos="0 -0.26156 0">
                    <inertial pos="-0.00028751 0.032222 0" quat="0.707106 0.707106 0.00103216 -0.00103216" mass="0.0099099" diaginertia="4.3337e-06 3.8298e-06 5.2164e-07"/>
                    <joint name="joint8" pos="0 0 0" axis="0 -1 0" range="-1 1" actuatorfrcrange="-100 100"/>
                    <geom type="mesh" rgba="0.37647 0.37647 0.37647 1" mesh="link_tool"/>
                  </body>
                </body>
              </body>
            </body>
          </body>
        </body>
      </body>
    </body>
  </worldbody>

    <actuator>
        <motor name="a1" ctrllimited="true" ctrlrange="-36.0 36.0"  joint="joint1"/>
        <motor name="a2" ctrllimited="true" ctrlrange="-36.0 36.0"  joint="joint2"/>
        <motor name="a3" ctrllimited="true" ctrlrange="-36.0 36.0"  joint="joint3"/>
        <motor name="a4" ctrllimited="true" ctrlrange="-36.0 36.0"  joint="joint4"/>
        <motor name="a5" ctrllimited="true" ctrlrange="-9.8 9.8"  joint="joint5"/>
        <motor name="a6" ctrllimited="true" ctrlrange="-9.8 9.8"  joint="joint6"/>
        <motor name="a7" ctrllimited="true" ctrlrange="-9.8 9.8"  joint="joint7"/>
        <motor name="a8" ctrllimited="true" ctrlrange="-0.01 0.01" joint="joint8"/>
  </actuator>

</mujoco>
